Workbook

Sheet Consolidate rows
A1: Consolidate rows in Excel with formulas
A2: Date | B2: Department | C2: Amount | E2: Department | F2: Amount
A3: 45658 | B3: Sales | C3: 1250 | E3: Sales | F3: 10960
A4: 45658 | B4: Marketing | C4: 980 | E4: Marketing | F4: 5280
A5: 45660 | B5: Sales | C5: 1540 | E5: Support | F5: 2690
A6: 45661 | B6: Support | C6: 620 | E6: Finance | F6: 8410
A7: 45662 | B7: Sales | C7: 1310
A8: 45663 | B8: Finance | C8: 2200
A9: 45664 | B9: Marketing | C9: 1120
A10: 45665 | B10: Support | C10: 700
A11: 45667 | B11: Sales | C11: 1890
A12: 45667 | B12: Finance | C12: 1760
A13: 45669 | B13: Marketing | C13: 1050
A14: 45669 | B14: Sales | C14: 1420
A15: 45670 | B15: Support | C15: 660
A16: 45671 | B16: Finance | C16: 2340
A17: 45672 | B17: Sales | C17: 1670
A18: 45673 | B18: Marketing | C18: 930
... A22: 45677 | B22: Marketing | C22: 1200

Sheet Consolidate columns
A1: Consolidate columns in Excel with formulas
A2: Department | B2: Jan | C2: Feb | D2: Mar | E2: Total | F2: Average
A3: Administration | B3: 1200 | C3: 1400 | D3: 1650 | E3: =SUM(B3:D3) -> 4250 | F3: =AVERAGE(B3:D3) -> 1416.6667
A4: Customer Support | B4: 1450 | C4: 1320 | D4: 1750 | E4: =SUM(B4:D4) -> 4520 | F4: =AVERAGE(B4:D4) -> 1506.6667
A5: Finance | B5: 1600 | C5: 1600 | D5: 1180 | E5: =SUM(B5:D5) -> 4380 | F5: =AVERAGE(B5:D5) -> 1460
A6: Human Resources | B6: 1150 | C6: 1750 | D6: 1450 | E6: =SUM(B6:D6) -> 4350 | F6: =AVERAGE(B6:D6) -> 1450
A7: Information Technology | B7: 1250 | C7: 1800 | D7: 2000 | E7: =SUM(B7:D7) -> 5050 | F7: =AVERAGE(B7:D7) -> 1683.3333
A8: Legal | B8: 1850 | C8: 1500 | D8: 1120 | E8: =SUM(B8:D8) -> 4470 | F8: =AVERAGE(B8:D8) -> 1490
A9: Logistics | B9: 1350 | C9: 1010 | D9: 1250 | E9: =SUM(B9:D9) -> 3610 | F9: =AVERAGE(B9:D9) -> 1203.3333
A10: Marketing | B10: 1200 | C10: 1550 | D10: 1550 | E10: =SUM(B10:D10) -> 4300 | F10: =AVERAGE(B10:D10) -> 1433.3333
A11: Operations | B11: 1950 | C11: 1700 | D11: 1900 | E11: =SUM(B11:D11) -> 5550 | F11: =AVERAGE(B11:D11) -> 1850
A12: Procurement | B12: 1350 | C12: 1080 | D12: 1500 | E12: =SUM(B12:D12) -> 3930 | F12: =AVERAGE(B12:D12) -> 1310
A13: Product Management | B13: 1400 | C13: 1000 | D13: 1650 | E13: =SUM(B13:D13) -> 4050 | F13: =AVERAGE(B13:D13) -> 1350
A14: Quality Assurance | B14: 1100 | C14: 1450 | D14: 1600 | E14: =SUM(B14:D14) -> 4150 | F14: =AVERAGE(B14:D14) -> 1383.3333
... A17: Training and Development | B17: 1500 | C17: 1050 | D17: 1400 | E17: =SUM(B17:D17) -> 3950 | F17: =AVERAGE(B17:D17) -> 1316.6667

Sheet Report 1
G1: Item | H1: Jan | I1: Feb | J1: Mar
G2: Biscuits | H2: 600 | I2: 310 | J2: 170
G3: Brownies | H3: 170 | I3: 250 | J3: 220
G4: Cakes | H4: 110 | J4: 340
G5: Candy Bars | H5: 120 | I5: 180 | J5: 160
G6: Cheesecake | H6: 210 | I6: 300 | J6: 270
G7: Chocolate | H7: 180 | I7: 260 | J7: 210
G8: Cookies | H8: 130 | I8: 190 | J8: 150
G9: Croissants | H9: 175 | I9: 245 | J9: 215
G10: Cupcakes | H10: 150 | I10: 210 | J10: 190
G11: Donuts | H11: 160 | J11: 180
G12: Fudge | H12: 165 | I12: 235 | J12: 205
G13: Ice-cream | H13: 110 | I13: 220 | J13: 160
G14: Macarons | H14: 220 | I14: 310 | J14: 280
G15: Muffins | H15: 140 | I15: 200 | J15: 170
G16: Pancakes | H16: 155 | I16: 215 | J16: 185
G17: Pastries | H17: 190 | I17: 270 | J17: 240
G18: Pies | H18: 200 | I18: 290
G19: Sweets | H19: 250 | I19: 140 | J19: 200
G20: Tarts | H20: 185 | I20: 265 | J20: 235
G21: Waffles | H21: 145 | I21: 205 | J21: 175

Sheet Report 2
F3: Item | G3: Jan | H3: Feb | I3: Mar
F4: Waffles | G4: 160 | H4: 170 | I4: 200
F5: Tarts | G5: 220 | H5: 270 | I5: 190
F6: Sweets | G6: 245 | H6: 240 | I6: 235
F7: Pies | G7: 140 | H7: 145 | I7: 140
F8: Pastries | G8: 130 | H8: 250 | I8: 190
F9: Pancakes | G9: 210 | H9: 110 | I9: 150
F10: Muffins | G10: 310 | H10: 150 | I10: 190
F11: Macarons | G11: 180 | H11: 290 | I11: 205
F12: Ice-cream | G12: 100 | H12: 210 | I12: 220
F13: Fudge | G13: 215 | H13: 200 | I13: 185
F14: Donuts | G14: 140 | H14: 215 | I14: 200
F15: Cupcakes | G15: 180 | H15: 210 | I15: 120
... F19: Cheesecake | G19: 180 | H19: 250 | I19: 165
F20: Candy Bars | G20: 280 | H20: 175
F21: Cakes | G21: 310 | I21: 220
F22: Brownies | G22: 235 | H22: 205 | I22: 175
F23: Biscuits | G23: 170 | H23: 185 | I23: 300

Sheet Report 3
A1: Item | B1: Jan | C1: Feb | D1: Mar
A2: Sweets | B2: 170 | C2: 400 | D2: 235
A3: Biscuits | B3: 155 | C3: 160 | D3: 260
A4: Ice-cream | B4: 320 | C4: 175 | D4: 235
A5: Cakes | B5: 270 | C5: 460 | D5: 190
A6: Chocolate | B6: 190 | C6: 160 | D6: 250
A7: Cookies | B7: 145 | C7: 220 | D7: 300
A8: Donuts | B8: 310 | C8: 140 | D8: 160
A9: Muffins | B9: 150 | C9: 250 | D9: 210
A10: Brownies | B10: 140 | C10: 270 | D10: 205
A11: Cupcakes | B11: 290 | C11: 245 | D11: 180
A12: Pastries | C12: 100 | D12: 220
A13: Candy Bars | B13: 190 | C13: 200 | D13: 120
A14: Pies | B14: 165 | D14: 130
A15: Waffles | B15: 200 | C15: 210 | D15: 175
A16: Pancakes | B16: 180 | C16: 280 | D16: 265
A17: Croissants | B17: 210 | C17: 310 | D17: 215
A18: Macarons | B18: 215 | C18: 185 | D18: 140
A19: Fudge | B19: 200 | C19: 240 | D19: 170
A20: Cheesecake | B20: 340 | C20: 170 | D20: 150
A21: Tarts | B21: 110 | C21: 220 | D21: 180

Sheet static
D5: Jan | E5: Feb | F5: Mar
C6: Biscuits | D6: 725 | E6: 655 | F6: 730
C7: Brownies | D7: 545 | E7: 725 | F7: 600
C8: Cakes | D8: 690 | E8: 460 | F8: 750
C9: Candy Bars | D9: 590 | E9: 555 | F9: 280
C10: Cheesecake | D10: 730 | E10: 720 | F10: 585
C11: Chocolate | D11: 710 | E11: 575 | F11: 630
C12: Cookies | D12: 540 | E12: 680 | F12: 710
C13: Croissants | D13: 545 | E13: 665 | F13: 590
C14: Cupcakes | D14: 620 | E14: 665 | F14: 490
C15: Donuts | D15: 610 | E15: 355 | F15: 540
C16: Fudge | D16: 580 | E16: 675 | F16: 560
C17: Ice-cream | D17: 530 | E17: 605 | F17: 615
... C25: Waffles | D25: 505 | E25: 585 | F25: 550

Sheet dynamic
G3: Jan | H3: Feb | I3: Mar
F4: Excel-Consolidate-Data | G4: ='Report 1'!$H$2 -> 600 | H4: ='Report 1'!$I$2 -> 310 | I4: ='Report 1'!$J$2 -> 170
F5: Excel-Consolidate-Data | G5: ='Report 2'!$G$23 -> 170 | H5: ='Report 2'!$H$23 -> 185 | I5: ='Report 2'!$I$23 -> 300
F6: Excel-Consolidate-Data | G6: ='Report 3'!$B$3 -> 155 | H6: ='Report 3'!$C$3 -> 160 | I6: ='Report 3'!$D$3 -> 260
E7: Biscuits | G7: =SUM(G4:G6) -> 925 | H7: =SUM(H4:H6) -> 655 | I7: =SUM(I4:I6) -> 730
F8: Excel-Consolidate-Data | G8: ='Report 1'!$H$3 -> 170 | H8: ='Report 1'!$I$3 -> 250 | I8: ='Report 1'!$J$3 -> 220
F9: Excel-Consolidate-Data | G9: ='Report 2'!$G$22 -> 235 | H9: ='Report 2'!$H$22 -> 205 | I9: ='Report 2'!$I$22 -> 175
F10: Excel-Consolidate-Data | G10: ='Report 3'!$B$10 -> 140 | H10: ='Report 3'!$C$10 -> 270 | I10: ='Report 3'!$D$10 -> 205
E11: Brownies | G11: =SUM(G8:G10) -> 545 | H11: =SUM(H8:H10) -> 725 | I11: =SUM(I8:I10) -> 600
F12: Excel-Consolidate-Data | G12: ='Report 1'!$H$4 -> 110 | I12: ='Report 1'!$J$4 -> 340
F13: Excel-Consolidate-Data | G13: ='Report 2'!$G$21 -> 310 | I13: ='Report 2'!$I$21 -> 220
F14: Excel-Consolidate-Data | G14: ='Report 3'!$B$5 -> 270 | H14: ='Report 3'!$C$5 -> 460 | I14: ='Report 3'!$D$5 -> 190
E15: Cakes | G15: =SUM(G12:G14) -> 690 | H15: =SUM(H12:H14) -> 460 | I15: =SUM(I12:I14) -> 750
F16: Excel-Consolidate-Data | G16: ='Report 1'!$H$5 -> 120 | H16: ='Report 1'!$I$5 -> 180 | I16: ='Report 1'!$J$5 -> 160
F17: Excel-Consolidate-Data | G17: ='Report 2'!$G$20 -> 280 | H17: ='Report 2'!$H$20 -> 175
F18: Excel-Consolidate-Data | G18: ='Report 3'!$B$13 -> 190 | H18: ='Report 3'!$C$13 -> 200 | I18: ='Report 3'!$D$13 -> 120
E19: Candy Bars | G19: =SUM(G16:G18) -> 590 | H19: =SUM(H16:H18) -> 555 | I19: =SUM(I16:I18) -> 280
F20: Excel-Consolidate-Data | G20: ='Report 1'!$H$6 -> 210 | H20: ='Report 1'!$I$6 -> 300 | I20: ='Report 1'!$J$6 -> 270
F21: Excel-Consolidate-Data | G21: ='Report 2'!$G$19 -> 180 | H21: ='Report 2'!$H$19 -> 250 | I21: ='Report 2'!$I$19 -> 165
F22: Excel-Consolidate-Data | G22: ='Report 3'!$B$20 -> 340 | H22: ='Report 3'!$C$20 -> 170 | I22: ='Report 3'!$D$20 -> 150
E23: Cheesecake | G23: =SUM(G20:G22) -> 730 | H23: =SUM(H20:H22) -> 720 | I23: =SUM(I20:I22) -> 585
F24: Excel-Consolidate-Data | G24: ='Report 1'!$H$7 -> 180 | H24: ='Report 1'!$I$7 -> 260 | I24: ='Report 1'!$J$7 -> 210
F25: Excel-Consolidate-Data | G25: ='Report 2'!$G$18 -> 340 | H25: ='Report 2'!$H$18 -> 155 | I25: ='Report 2'!$I$18 -> 170
F26: Excel-Consolidate-Data | G26: ='Report 3'!$B$6 -> 190 | H26: ='Report 3'!$C$6 -> 160 | I26: ='Report 3'!$D$6 -> 250
E27: Chocolate | G27: =SUM(G24:G26) -> 710 | H27: =SUM(H24:H26) -> 575 | I27: =SUM(I24:I26) -> 630
F28: Excel-Consolidate-Data | G28: ='Report 1'!$H$8 -> 130 | H28: ='Report 1'!$I$8 -> 190 | I28: ='Report 1'!$J$8 -> 150
F29: Excel-Consolidate-Data | G29: ='Report 2'!$G$17 -> 265 | H29: ='Report 2'!$H$17 -> 270 | I29: ='Report 2'!$I$17 -> 260
F30: Excel-Consolidate-Data | G30: ='Report 3'!$B$7 -> 145 | H30: ='Report 3'!$C$7 -> 220 | I30: ='Report 3'!$D$7 -> 300
E31: Cookies | G31: =SUM(G28:G30) -> 540 | H31: =SUM(H28:H30) -> 680 | I31: =SUM(I28:I30) -> 710
F32: Excel-Consolidate-Data | G32: ='Report 1'!$H$9 -> 175 | H32: ='Report 1'!$I$9 -> 245 | I32: ='Report 1'!$J$9 -> 215
F33: Excel-Consolidate-Data | G33: ='Report 2'!$G$16 -> 160 | H33: ='Report 2'!$H$16 -> 110 | I33: ='Report 2'!$I$16 -> 160
F34: Excel-Consolidate-Data | G34: ='Report 3'!$B$17 -> 210 | H34: ='Report 3'!$C$17 -> 310 | I34: ='Report 3'!$D$17 -> 215
E35: Croissants | G35: =SUM(G32:G34) -> 545 | H35: =SUM(H32:H34) -> 665 | I35: =SUM(I32:I34) -> 590
F36: Excel-Consolidate-Data | G36: ='Report 1'!$H$10 -> 150 | H36: ='Report 1'!$I$10 -> 210 | I36: ='Report 1'!$J$10 -> 190
F37: Excel-Consolidate-Data | G37: ='Report 2'!$G$15 -> 180 | H37: ='Report 2'!$H$15 -> 210 | I37: ='Report 2'!$I$15 -> 120
F38: Excel-Consolidate-Data | G38: ='Report 3'!$B$11 -> 290 | H38: ='Report 3'!$C$11 -> 245 | I38: ='Report 3'!$D$11 -> 180
E39: Cupcakes | G39: =SUM(G36:G38) -> 620 | H39: =SUM(H36:H38) -> 665 | I39: =SUM(I36:I38) -> 490
F40: Excel-Consolidate-Data | G40: ='Report 1'!$H$11 -> 160 | I40: ='Report 1'!$J$11 -> 180
F41: Excel-Consolidate-Data | G41: ='Report 2'!$G$14 -> 140 | H41: ='Report 2'!$H$14 -> 215 | I41: ='Report 2'!$I$14 -> 200
F42: Excel-Consolidate-Data | G42: ='Report 3'!$B$8 -> 310 | H42: ='Report 3'!$C$8 -> 140 | I42: ='Report 3'!$D$8 -> 160
...
